<?xml version="1.0"?>
<robot name="/home/asger/P10-XRL/GymEnvironments/P12-RL-Level2DQN/P10_LEVEL2_DQN/envs/Robot.urdf" xmlns:xacro="http://ros.org/wiki/xacro">
  <link name="base_link">
  </link>
  <joint name="shoulder_pan_joint" type="revolute">
    <parent link="base_link"/>
    <child link="shoulder_link"/>
    <axis xyz="-2.5407024e-05 -8.646952e-06 1"/>
    <limit effort="330" lower="-6.28319" upper="6.28319" velocity="3.14"/>
    <origin xyz="0 0 0.152" rpy="-8.646952e-06 2.5407024e-05 0.74997705"/>
  </joint>
  <link name="shoulder_link">
  </link>
  <joint name="shoulder_lift_joint" type="revolute">
    <parent link="shoulder_link"/>
    <child link="upper_arm_link"/>
    <axis xyz="3.1818875e-06 1 9.324208e-10"/>
    <limit effort="330" lower="-6.28319" upper="6.28319" velocity="3.14"/>
    <origin xyz="5.1591864e-09 0.12 -0.00013796563" rpy="5.827552e-06 1.0710908 6.6404546e-06"/>
  </joint>
  <link name="upper_arm_link">
  </link>
  <joint name="elbow_joint" type="revolute">
    <parent link="upper_arm_link"/>
    <child link="forearm_link"/>
    <axis xyz="-1.702596e-06 1 -3.9761937e-11"/>
    <limit effort="150" lower="-3.14159" upper="3.14159" velocity="3.14"/>
    <origin xyz="0.00010691819 -0.092999995 0.244" rpy="-9.303607e-07 0.50012124 -1.9402264e-06"/>
  </joint>
  <link name="forearm_link">
  </link>
  <link name="touch_sensor2">
  </link>
  <joint name="forearm_link_touch_sensor2_joint" type="fixed">
    <parent link="forearm_link"/>
    <child link="touch_sensor2"/>
    <origin xyz="5.290666e-05 0.060000002 5.5261884e-09" rpy="0 0 0"/>
  </joint>
  <joint name="wrist_1_joint" type="revolute">
    <parent link="forearm_link"/>
    <child link="wrist_1_link"/>
    <axis xyz="1.7306057e-10 1 -1.7383829e-06"/>
    <limit effort="54" lower="-6.28319" upper="6.28319" velocity="6.28"/>
    <origin xyz="0 0 0.213" rpy="1.7383832e-06 0.0008133543 1.7306062e-10"/>
  </joint>
  <link name="wrist_1_link">
  </link>
  <joint name="wrist_2_joint" type="revolute">
    <parent link="wrist_1_link"/>
    <child link="wrist_2_link"/>
    <axis xyz="0 0 1"/>
    <limit effort="54" lower="-6.28319" upper="6.28319" velocity="6.28"/>
    <origin xyz="-3.0226173e-09 0.104 3.03729e-05" rpy="0 0 -1.57"/>
  </joint>
  <link name="wrist_2_link">
  </link>
  <joint name="wrist_3_joint" type="revolute">
    <parent link="wrist_2_link"/>
    <child link="wrist_3_link"/>
    <axis xyz="0 1 0"/>
    <limit effort="54" lower="-6.28319" upper="6.28319" velocity="6.28"/>
    <origin xyz="-1.6733003e-09 3.8016598e-10 0.085016735" rpy="0 0 0"/>
  </joint>
  <link name="wrist_3_link">
  </link>
  <link name="touch_sensor4">
  </link>
  <joint name="wrist_3_link_touch_sensor4_joint" type="fixed">
    <parent link="wrist_3_link"/>
    <child link="touch_sensor4"/>
    <origin xyz="-4.0283737e-10 0.022 4.092633e-06" rpy="0 0 0"/>
  </joint>
  <joint name="right_finger" type="prismatic">
    <parent link="wrist_3_link"/>
    <child link="box(2)"/>
    <axis xyz="1 -9.912553e-08 8.168981e-09"/>
    <origin xyz="0.02 0.229637 -3.59221e-09" rpy="-3.592219e-08 8.168985e-09 9.912553e-08"/>
    <limit effort="214" lower="0" upper="10" velocity="10"/>
  </joint>
  <link name="box(2)">
  </link>
  <link name="box(1)">
  </link>
  <joint name="wrist_3_link_box(1)_joint" type="fixed">
    <parent link="wrist_3_link"/>
    <child link="box(1)"/>
    <origin xyz="0.039999995 0.14 3.2675923e-10" rpy="0 0 0"/>
  </joint>
  <link name="distance_sensor1">
  </link>
  <joint name="wrist_3_link_distance_sensor1_joint" type="fixed">
    <parent link="wrist_3_link"/>
    <child link="distance_sensor1"/>
    <origin xyz="-0.00500261 0.22 0" rpy="0 0 1.57081"/>
  </joint>
  <joint name="left_finger" type="prismatic">
    <parent link="wrist_3_link"/>
    <child link="box"/>
    <axis xyz="-1 3.6009387e-05 1.0512928e-06"/>
    <origin xyz="-0.0187949 0.230475 0.000351439" rpy="0.0035143727 -1.1778365e-06 3.6005473e-05"/>
    <limit effort="214" velocity="10"/>
  </joint>
  <link name="box">
  </link>
  <link name="connector">
  </link>
  <joint name="wrist_3_link_connector_joint" type="fixed">
    <parent link="wrist_3_link"/>
    <child link="connector"/>
    <origin xyz="-0.039999995 0.25000143 1.15515604e-07" rpy="1.5707949 1.738044e-06 3.1415906"/>
  </joint>
  <link name="tcp_solid">
  </link>
  <joint name="wrist_3_link_tcp_solid_joint" type="fixed">
    <parent link="wrist_3_link"/>
    <child link="tcp_solid"/>
    <origin xyz="0 0.25 0" rpy="0 0.2617953 0"/>
  </joint>
  <link name="y">
  </link>
  <joint name="wrist_3_link_y_joint" type="fixed">
    <parent link="wrist_3_link"/>
    <child link="y"/>
    <origin xyz="0 0.28 0" rpy="0 0.2617953 0"/>
  </joint>
  <link name="y(1)">
  </link>
  <joint name="wrist_3_link_y(1)_joint" type="fixed">
    <parent link="wrist_3_link"/>
    <child link="y(1)"/>
    <origin xyz="0 0.35 0" rpy="0 0.2617953 0"/>
  </joint>
  <link name="touch_sensor3">
  </link>
  <joint name="wrist_1_link_touch_sensor3_joint" type="fixed">
    <parent link="wrist_1_link"/>
    <child link="touch_sensor3"/>
    <origin xyz="0 0.05 0" rpy="0 0 0"/>
  </joint>
  <link name="touch_sensor5">
  </link>
  <joint name="forearm_link_touch_sensor5_joint" type="fixed">
    <parent link="forearm_link"/>
    <child link="touch_sensor5"/>
    <origin xyz="0 -4.04052e-07 0.11" rpy="1.5708 0 0"/>
  </joint>
  <link name="touch_sensor6">
  </link>
  <joint name="upper_arm_link_touch_sensor6_joint" type="fixed">
    <parent link="upper_arm_link"/>
    <child link="touch_sensor6"/>
    <origin xyz="0 -4.77516e-07 0.13" rpy="1.5708 0 0"/>
  </joint>
  <link name="touch_sensor1">
  </link>
  <joint name="shoulder_link_touch_sensor1_joint" type="fixed">
    <parent link="shoulder_link"/>
    <child link="touch_sensor1"/>
    <origin xyz="0 0.07 0" rpy="0 0 0"/>
  </joint>
  <link name="touch_sensor7">
  </link>
  <joint name="base_link_touch_sensor7_joint" type="fixed">
    <parent link="base_link"/>
    <child link="touch_sensor7"/>
    <origin xyz="0 -1.8366e-07 0.05" rpy="1.5708 0 0"/>
  </joint>
  <link name="camera">
  </link>
  <joint name="base_link_camera_joint" type="fixed">
    <parent link="base_link"/>
    <child link="camera"/>
    <origin xyz="-0.319994 -0.26 1.95" rpy="3.468237e-06 -4.837896e-07 -1.57081"/>
  </joint>
  <link name="Kinect">
    <visual>
      <origin xyz="0 0.0135 0" rpy="0 0 0"/>
      <geometry>
        <box size="0.084 0.027 0.068"/>
      </geometry>
    </visual>
    <collision>
      <origin xyz="0 0.0135 0" rpy="0 0 0"/>
      <geometry>
        <box size="0.084 0.027 0.068"/>
      </geometry>
    </collision>
  </link>
  <joint name="camera_Kinect_joint" type="fixed">
    <parent link="camera"/>
    <child link="Kinect"/>
    <origin xyz="0.04 -3.5382197e-11 0.15997648" rpy="-1.7170105e-07 -1.4390256e-20 -1.2793447e-13"/>
  </joint>
  <joint name="tilt motor" type="revolute">
    <parent link="Kinect"/>
    <child link="solid"/>
    <axis xyz="1 -8.4703295e-22 -1.6940659e-21"/>
    <limit effort="10" lower="-0.47" upper="0.47" velocity="10"/>
    <origin xyz="0 0.05 0" rpy="-4.440892e-16 -1.6940659e-21 8.4703295e-22"/>
  </joint>
  <link name="solid">
  </link>
  <link name="kinect range">
  </link>
  <joint name="solid_kinect range_joint" type="fixed">
    <parent link="solid"/>
    <child link="kinect range"/>
    <origin xyz="-0.0127 0 0" rpy="0 0 0"/>
  </joint>
  <link name="kinect color">
  </link>
  <joint name="solid_kinect color_joint" type="fixed">
    <parent link="solid"/>
    <child link="kinect color"/>
    <origin xyz="0.0127 0 0" rpy="0 0 0"/>
  </joint>
  <link name="display_explanation">
  </link>
  <joint name="base_link_display_explanation_joint" type="fixed">
    <parent link="base_link"/>
    <child link="display_explanation"/>
    <origin xyz="0.620001 0.02 0.939999" rpy="3.1415894 -7.061466e-06 -1.5707921"/>
  </joint>
  <link name="appearance">
  </link>
  <joint name="display_explanation_appearance_joint" type="fixed">
    <parent link="display_explanation"/>
    <child link="appearance"/>
    <origin xyz="0 0 0" rpy="0 0 0"/>
  </joint>
  <link name="solid_0">
  </link>
  <joint name="base_link_solid_0_joint" type="fixed">
    <parent link="base_link"/>
    <child link="solid_0"/>
    <origin xyz="-1.18 -0.34 0.94" rpy="0 0 -5.3071794e-06"/>
  </joint>
</robot>
